<?xml version="1.0" encoding="UTF-8"?>
<sdf version="1.9">
  <model name="b3rb">
    <self_collide>false</self_collide>
    <static>false</static>

    <!-- -->

    <link name="base_link">
      <pose>0 0 0.00 0 0 0</pose>
      <inertial>
        <pose>0 0 0 0 0 0</pose>
        <mass>3.0</mass>
        <inertia>
          <ixx>0.0054</ixx>
          <ixy>0</ixy>
          <ixz>0</ixz>
          <iyy>0.0252</iyy>
          <iyz>0</iyz>
          <izz>0.0252</izz>
        </inertia>
      </inertial>
      <visual name="BaseVisual">
        <pose>0.002 0 -0.005 0 0 -1.5707</pose>
        <geometry>
          <mesh>
            <uri>file:///home/user/workspace/PX4-Autopilot/Tools/simulation/gz/models/b3rb/meshes/b3rb.dae</uri>
          </mesh>
        </geometry>
      </visual>
      <collision name="BaseCollision">
        <pose>0 0 .06 0 0 0</pose>
        <geometry>
          <box>
            <size>.34 .09 .14</size>
          </box>
        </geometry>
      </collision>
      <sensor name="imu_sensor" type="imu">
        <always_on>1</always_on>
        <update_rate>250</update_rate>
        <imu>
          <angular_velocity>
            <x>
              <noise type="gaussian">
                <mean>0</mean>
                <stddev>0.0003394</stddev>
                <dynamic_bias_stddev>3.8785e-05</dynamic_bias_stddev>
                <dynamic_bias_correlation_time>1000</dynamic_bias_correlation_time>
              </noise>
            </x>
            <y>
              <noise type="gaussian">
                <mean>0</mean>
                <stddev>0.0003394</stddev>
                <dynamic_bias_stddev>3.8785e-05</dynamic_bias_stddev>
                <dynamic_bias_correlation_time>1000</dynamic_bias_correlation_time>
              </noise>
            </y>
            <z>
              <noise type="gaussian">
                <mean>0</mean>
                <stddev>0.0003394</stddev>
                <dynamic_bias_stddev>3.8785e-05</dynamic_bias_stddev>
                <dynamic_bias_correlation_time>1000</dynamic_bias_correlation_time>
              </noise>
            </z>
          </angular_velocity>
          <linear_acceleration>
            <x>
              <noise type="gaussian">
                <mean>0</mean>
                <stddev>0.004</stddev>
                <dynamic_bias_stddev>0.0006</dynamic_bias_stddev>
                <dynamic_bias_correlation_time>300</dynamic_bias_correlation_time>
              </noise>
            </x>
            <y>
              <noise type="gaussian">
                <mean>0</mean>
                <stddev>0.004</stddev>
                <dynamic_bias_stddev>0.0006</dynamic_bias_stddev>
                <dynamic_bias_correlation_time>300</dynamic_bias_correlation_time>
              </noise>
            </y>
            <z>
              <noise type="gaussian">
                <mean>0</mean>
                <stddev>0.004</stddev>
                <dynamic_bias_stddev>0.0006</dynamic_bias_stddev>
                <dynamic_bias_correlation_time>300</dynamic_bias_correlation_time>
              </noise>
            </z>
          </linear_acceleration>
        </imu>
      </sensor>
	    <sensor name="magnetometer_sensor" type="magnetometer">
	    	<always_on>1</always_on>
	    	<update_rate>100</update_rate>
	    	<magnetometer>
	    		<!-- TODO: update to fix units and coordinate system when we move past Harmonic -->
	    		<!-- See https://github.com/gazebosim/gz-sim/pull/2460 -->
	    		<!-- 3mgauss RMS: NOTE: noise is in tesla but sensor reports data in gauss -->
	    		<!-- Noise modeled after IIS2MDC -->
	    		<x>
	    			<noise type="gaussian">
	    			<stddev>0.0001</stddev>
	    			</noise>
	    		</x>
	    		<y>
	    			<noise type="gaussian">
	    			<stddev>0.0001</stddev>
	    			</noise>
	    		</y>
	    		<z>
	    			<noise type="gaussian">
	    			<stddev>0.0001</stddev>
	    			</noise>
	    		</z>
	    	</magnetometer>
	    </sensor>
      <sensor name="navsat_sensor" type="navsat">
        <always_on>1</always_on>
        <update_rate>20</update_rate>
        <navsat>
          <position_sensing></position_sensing>
          <velocity_sensing></velocity_sensing>
        </navsat>
      </sensor>
      <sensor name="air_pressure_sensor" type="air_pressure">
        <always_on>1</always_on>
        <update_rate>50</update_rate>
        <air_pressure>
          <pressure>
            <noise type="gaussian">
              <mean>0</mean>
              <stddev>0.01</stddev>
            </noise>
          </pressure>
        </air_pressure>
      </sensor>
    </link>

    <!-- -->

    <link name="realsense_camera_link">
      <pose relative_to='base_link'>0 0 0.6 0 0.5235988 0</pose>
      <inertial>
        <mass>0.003</mass>
        <inertia>
          <ixx>0.0000000294</ixx>
          <ixy>0</ixy>
          <ixz>0</ixz>
          <iyy>0.0000000294</iyy>
          <iyz>0</iyz>
          <izz>0.0000000392</izz>
        </inertia>
      </inertial>
      <visual name="camera_housing">
        <pose>0 0 0 0 0 0</pose>
        <geometry>
          <box>
            <size>0.025 0.09 0.025</size>
          </box>
        </geometry>
        <material>
          <ambient>0.2 0.2 0.2 1</ambient>
          <diffuse>0.8 0.8 0.8 1</diffuse>
        </material>
      </visual>
      <sensor name="d435i_rgb" type="camera">
        <pose>0 0 0 0 0 0</pose>
        <camera>
          <camera_info_topic>camera/color/camera_info</camera_info_topic>
          <horizontal_fov>0.96921075</horizontal_fov>
          <image>
            <width>640</width>
            <height>480</height>
            <format>R8G8B8</format>
          </image>
          <clip>
            <near>0.1</near>
            <far>100</far>
          </clip>
        </camera>
        <topic>camera/color/image_raw</topic>
        <update_rate>30</update_rate>
        <visualize>true</visualize>
        <always_on>1</always_on>
      </sensor>
      <sensor name="d435i_depth" type="depth_camera">
        <pose>0 0 0 0 0 0</pose>
        <camera>
          <horizontal_fov>0.96921075</horizontal_fov>
          <image>
            <width>640</width>
            <height>480</height>
            <!-- Gazebo depth camera formats can be L16 or R_FLOAT32 -->
            <format>R_FLOAT32</format>
          </image>
          <clip>
            <near>0.1</near>
            <far>100</far>
          </clip>
        </camera>
        <topic>camera/aligned_depth_to_color/image_raw</topic>
        <update_rate>30</update_rate>
        <visualize>false</visualize> <!-- Depth images are often not visualized directly -->
        <always_on>1</always_on>
      </sensor>
    </link>

    <joint name="realsense_camera_joint" type="fixed">
      <parent>base_link</parent>
      <child>realsense_camera_link</child>
    </joint>

    <!-- -->

    <link name="FrontRightWheel">
      <pose relative_to="FrontRightWheelJoint">0 0 0 0 0 0</pose>
      <inertial>
        <mass>.05</mass>
        <inertia>
          <ixx>0.00003331</ixx>
          <ixy>0</ixy>
          <ixz>0</ixz>
          <iyy>0.0000204</iyy>
          <iyz>0</iyz>
          <izz>0.0000204</izz>
        </inertia>
      </inertial>
      <gravity>true</gravity>
      <velocity_decay />
      <visual name="FrontRightWheelVisual">
        <pose>0 0 0 0 0 0</pose>
        <geometry>
          <mesh>
            <uri>file:///home/user/workspace/PX4-Autopilot/Tools/simulation/gz/models/b3rb/meshes/wheel.dae</uri>
          </mesh>
        </geometry>
      </visual>
      <collision name="FrontRightWheelCollision">
        <pose>0 .015 0 -1.5707 0 0</pose>
        <geometry>
          <cylinder>
            <length>0.03</length>
            <radius>0.0365</radius>
          </cylinder>
        </geometry>
        <surface>
          <friction>
            <ode>
              <mu>5.0</mu>
              <mu2>2.5</mu2>
              <fdir1>0 0 1</fdir1>
            </ode>
          </friction>
        </surface>
      </collision>
    </link>

    <link name="FrontRightWheelSteering">
      <pose relative_to="FrontRightWheelSteeringJoint">0 0 0 0 0 0</pose>
      <inertial>
        <mass>0.005</mass>
        <inertia>
          <ixx>0.0000018</ixx>
          <iyy>0.0000018</iyy>
          <izz>0.0000018</izz>
        </inertia>
      </inertial>
    </link>

    <joint name="FrontRightWheelSteeringJoint" type="revolute">
      <parent>base_link</parent>
      <child>FrontRightWheelSteering</child>
      <pose relative_to="base_link">.112 -.10 0 0 0 0</pose>
      <axis>
        <xyz>0 0 1</xyz>
        <limit>
          <lower>-0.6</lower>
          <upper>0.6</upper>
          <velocity>1000</velocity>
          <effort>1000</effort>
        </limit>
      </axis>
    </joint>

    <joint name="FrontRightWheelJoint" type="revolute">
      <parent>FrontRightWheelSteering</parent>
      <child>FrontRightWheel</child>
      <pose relative_to="FrontRightWheelSteeringJoint">0 0 0 0 0 0</pose>
      <axis>
        <xyz>0 1 0</xyz>
        <limit>
          <lower>-1.79769e+308</lower>
          <upper>1.79769e+308</upper>
        </limit>
        <dynamics>
          <spring_reference>0</spring_reference>
          <spring_stiffness>0</spring_stiffness>
        </dynamics>
      </axis>
    </joint>

    <!-- -->

    <link name="FrontLeftWheel">
      <pose relative_to="FrontLeftWheelJoint">0 0 0 0 0 0</pose>
      <inertial>
        <mass>.05</mass>
        <inertia>
          <ixx>0.00003331</ixx>
          <ixy>0</ixy>
          <ixz>0</ixz>
          <iyy>0.0000204</iyy>
          <iyz>0</iyz>
          <izz>0.0000204</izz>
        </inertia>
      </inertial>
      <gravity>true</gravity>
      <velocity_decay />
      <visual name="FrontLeftWheelVisual">
        <pose>0 0 0 0 0 3.14159</pose>
        <geometry>
          <mesh>
            <uri>file:///home/user/workspace/PX4-Autopilot/Tools/simulation/gz/models/b3rb/meshes/wheel.dae</uri>
          </mesh>
        </geometry>
      </visual>
      <collision name="FrontLeftWheelCollision">
        <pose>0 -.015 0 -1.5707 0 0</pose>
        <geometry>
          <cylinder>
            <length>0.03</length>
            <radius>0.0365</radius>
          </cylinder>
        </geometry>
        <surface>
          <friction>
            <ode>
              <mu>5.0</mu>
              <mu2>2.5</mu2>
              <fdir1>0 0 1</fdir1>
            </ode>
          </friction>
        </surface>
      </collision>
    </link>

    <link name="FrontLeftWheelSteering">
      <pose relative_to="FrontLeftWheelSteeringJoint">0 0 0 0 0 0</pose>
      <inertial>
        <mass>0.005</mass>
        <inertia>
          <ixx>0.0000018</ixx>
          <iyy>0.0000018</iyy>
          <izz>0.0000018</izz>
        </inertia>
      </inertial>
    </link>

    <joint name="FrontLeftWheelSteeringJoint" type="revolute">
      <parent>base_link</parent>
      <child>FrontLeftWheelSteering</child>
      <pose relative_to="base_link">.112 .10 0 0 0 0</pose>
      <axis>
        <xyz>0 0 1</xyz>
        <limit>
          <lower>-0.6</lower>
          <upper>0.6</upper>
          <velocity>1000</velocity>
          <effort>1000</effort>
        </limit>
      </axis>
    </joint>

    <joint name="FrontLeftWheelJoint" type="revolute">
      <parent>FrontLeftWheelSteering</parent>
      <child>FrontLeftWheel</child>
      <pose relative_to="FrontLeftWheelSteeringJoint">0 0 0 0 0 0</pose>
      <axis>
        <xyz>0 1 0</xyz>
        <limit>
          <lower>-1.79769e+308</lower>
          <upper>1.79769e+308</upper>
        </limit>
        <dynamics>
          <spring_reference>0</spring_reference>
          <spring_stiffness>0</spring_stiffness>
        </dynamics>
      </axis>
    </joint>

    <!-- -->

    <joint name="RearRightWheelJoint" type="revolute">
      <parent>base_link</parent>
      <child>RearRightWheel</child>
      <pose relative_to="base_link">-.1135 -.10 0 0 0 0</pose>
      <axis>
        <xyz>0 1 0</xyz>
        <limit>
          <lower>-1.79769e+308</lower>
          <upper>1.79769e+308</upper>
        </limit>
        <dynamics>
          <spring_reference>0</spring_reference>
          <spring_stiffness>0</spring_stiffness>
        </dynamics>
      </axis>
    </joint>

    <joint name="RearLeftWheelJoint" type="revolute">
      <parent>base_link</parent>
      <child>RearLeftWheel</child>
      <pose relative_to="base_link">-.1135 .10 0 0 0 0</pose>
      <axis>
        <xyz>0 1 0</xyz>
        <limit>
          <lower>-1.79769e+308</lower>
          <upper>1.79769e+308</upper>
        </limit>
        <dynamics>
          <spring_reference>0</spring_reference>
          <spring_stiffness>0</spring_stiffness>
        </dynamics>
      </axis>
    </joint>

    <link name="RearRightWheel">
      <pose relative_to="RearRightWheelJoint">0 0 0 0 0 0</pose>
      <inertial>
        <mass>.05</mass>
        <inertia>
          <ixx>0.00003331</ixx>
          <ixy>0</ixy>
          <ixz>0</ixz>
          <iyy>0.0000204</iyy>
          <iyz>0</iyz>
          <izz>0.0000204</izz>
        </inertia>
      </inertial>
      <gravity>true</gravity>
      <velocity_decay />
      <visual name="RearRightWheelVisual">
        <pose>0 0 0 0 0 0</pose>
        <geometry>
          <mesh>
            <uri>file:///home/user/workspace/PX4-Autopilot/Tools/simulation/gz/models/b3rb/meshes/wheel.dae</uri>
          </mesh>
        </geometry>
      </visual>
      <collision name="RearRightWheelCollision">
        <pose>0 .015 0 -1.5707 0 0</pose>
        <geometry>
          <cylinder>
            <length>0.03</length>
            <radius>0.0365</radius>
          </cylinder>
        </geometry>
        <surface>
          <friction>
            <ode>
              <mu>5.0</mu>
              <mu2>2.5</mu2>
              <fdir1>0 0 1</fdir1>
            </ode>
          </friction>
        </surface>
      </collision>
    </link>

    <link name="RearLeftWheel">
      <pose relative_to="RearLeftWheelJoint">0 0 0 0 0 0</pose>
      <inertial>
        <mass>.05</mass>
        <inertia>
          <ixx>0.00003331</ixx>
          <ixy>0</ixy>
          <ixz>0</ixz>
          <iyy>0.0000204</iyy>
          <iyz>0</iyz>
          <izz>0.0000204</izz>
        </inertia>
      </inertial>
      <gravity>true</gravity>
      <velocity_decay />
      <visual name="RearLeftWheelVisual">
        <pose>0 0 0 0 0 3.14159</pose>
        <geometry>
          <mesh>
            <uri>file:///home/user/workspace/PX4-Autopilot/Tools/simulation/gz/models/b3rb/meshes/wheel.dae</uri>
          </mesh>
        </geometry>
      </visual>
      <collision name="RearLeftWheelCollision">
        <pose>0 -.015 0 -1.5707 0 0</pose>
        <geometry>
          <cylinder>
            <length>0.03</length>
            <radius>0.0365</radius>
          </cylinder>
        </geometry>
        <surface>
          <friction>
            <ode>
              <mu>5.0</mu>
              <mu2>2.5</mu2>
              <fdir1>0 0 1</fdir1>
            </ode>
          </friction>
        </surface>
      </collision>
    </link>

    <!-- -->

    <plugin
      filename="gz-sim-odometry-publisher-system"
      name="gz::sim::systems::OdometryPublisher">
      <xyz_offset>0 0 0</xyz_offset>
      <rpy_offset>0 0 0</rpy_offset>
      <gaussian_noise>0</gaussian_noise>
      <robot_base_frame>base_link</robot_base_frame>
      <dimensions>3</dimensions>
      <odom_publish_frequency>50</odom_publish_frequency>
      <odom_frame>odom</odom_frame>
    </plugin>

    <plugin
      filename="gz-sim-ackermann-steering-system"
      name="gz::sim::systems::AckermannSteering">
      <steering_only>true</steering_only>
      <use_actuator_msg>true</use_actuator_msg>
      <sub_topic>servo_0</sub_topic>
      <left_steering_joint>FrontLeftWheelSteeringJoint</left_steering_joint>
      <right_steering_joint>FrontRightWheelSteeringJoint</right_steering_joint>
      <steering_limit>0.4</steering_limit>
      <steer_p_gain>8.0</steer_p_gain>
      <wheel_base>.2255</wheel_base>
      <wheel_separation>.2</wheel_separation>
    </plugin>

    <plugin
      filename="gz-sim-joint-controller-system"
      name="gz::sim::systems::JointController">
      <joint_name>RearRightWheelJoint</joint_name>
      <joint_name>RearLeftWheelJoint</joint_name>
      <joint_name>FrontRightWheelJoint</joint_name>
      <joint_name>FrontLeftWheelJoint</joint_name>
      <use_actuator_msg>true</use_actuator_msg>
      <actuator_number>0</actuator_number>
      <sub_topic>command/motor_speed</sub_topic>
    </plugin>

    <plugin
      filename="gz-sim-joint-state-publisher-system"
      name="gz::sim::systems::JointStatePublisher">
      <joint_name>RearRightWheelJoint</joint_name>
      <joint_name>RearLeftWheelJoint</joint_name>
      <joint_name>FrontRightWheelJoint</joint_name>
      <joint_name>FrontLeftWheelJoint</joint_name>
    </plugin>

    <!-- -->

  </model>
</sdf>
